
2022-07-28 19:18:42 [ERROR] 
Traceback (most recent call last):
  File "/usr/local/lib/python3.8/site-packages/django/db/models/fields/__init__.py", line 2434, in to_python
    return uuid.UUID(**{input_form: value})
  File "/usr/local/lib/python3.8/uuid.py", line 171, in __init__
    raise ValueError('badly formed hexadecimal UUID string')
ValueError: badly formed hexadecimal UUID string

During handling of the above exception, another exception occurred:

Traceback (most recent call last):
  File "/usr/local/lib/python3.8/site-packages/rest_framework/views.py", line 497, in dispatch
    self.initial(request, *args, **kwargs)
  File "/usr/local/lib/python3.8/site-packages/rest_framework/views.py", line 414, in initial
    self.perform_authentication(request)
  File "/usr/local/lib/python3.8/site-packages/rest_framework/views.py", line 324, in perform_authentication
    request.user
  File "/usr/local/lib/python3.8/site-packages/rest_framework/request.py", line 227, in user
    self._authenticate()
  File "/usr/local/lib/python3.8/site-packages/rest_framework/request.py", line 380, in _authenticate
    user_auth_tuple = authenticator.authenticate(self)
  File "/opt/jumpserver/apps/common/auth/signature.py", line 82, in authenticate
    user, secret = self.fetch_user_data(
  File "/opt/jumpserver/apps/authentication/backends/drf.py", line 196, in fetch_user_data
    key = AccessKey.objects.get(id=key_id)
  File "/usr/local/lib/python3.8/site-packages/django/db/models/manager.py", line 85, in manager_method
    return getattr(self.get_queryset(), name)(*args, **kwargs)
  File "/usr/local/lib/python3.8/site-packages/django/db/models/query.py", line 424, in get
    clone = self._chain() if self.query.combinator else self.filter(*args, **kwargs)
  File "/usr/local/lib/python3.8/site-packages/django/db/models/query.py", line 941, in filter
    return self._filter_or_exclude(False, args, kwargs)
  File "/usr/local/lib/python3.8/site-packages/django/db/models/query.py", line 961, in _filter_or_exclude
    clone._filter_or_exclude_inplace(negate, args, kwargs)
  File "/usr/local/lib/python3.8/site-packages/django/db/models/query.py", line 968, in _filter_or_exclude_inplace
    self._query.add_q(Q(*args, **kwargs))
  File "/usr/local/lib/python3.8/site-packages/django/db/models/sql/query.py", line 1416, in add_q
    clause, _ = self._add_q(q_object, self.used_aliases)
  File "/usr/local/lib/python3.8/site-packages/django/db/models/sql/query.py", line 1435, in _add_q
    child_clause, needed_inner = self.build_filter(
  File "/usr/local/lib/python3.8/site-packages/django/db/models/sql/query.py", line 1370, in build_filter
    condition = self.build_lookup(lookups, col, value)
  File "/usr/local/lib/python3.8/site-packages/django/db/models/sql/query.py", line 1216, in build_lookup
    lookup = lookup_class(lhs, rhs)
  File "/usr/local/lib/python3.8/site-packages/django/db/models/lookups.py", line 25, in __init__
    self.rhs = self.get_prep_lookup()
  File "/usr/local/lib/python3.8/site-packages/django/db/models/lookups.py", line 77, in get_prep_lookup
    return self.lhs.output_field.get_prep_value(self.rhs)
  File "/usr/local/lib/python3.8/site-packages/django/db/models/fields/__init__.py", line 2418, in get_prep_value
    return self.to_python(value)
  File "/usr/local/lib/python3.8/site-packages/django/db/models/fields/__init__.py", line 2436, in to_python
    raise exceptions.ValidationError(
django.core.exceptions.ValidationError: ['“”不是一个有效的UUID']
